#VRML_SIM R2023b utf8

EXTERNPROTO "https://raw.githubusercontent.com/cyberbotics/webots/R2023b/projects/appearances/protos/BrushedSteel.proto"
EXTERNPROTO "https://raw.githubusercontent.com/cyberbotics/webots/R2023b/projects/appearances/protos/Copper.proto"
EXTERNPROTO "https://raw.githubusercontent.com/cyberbotics/webots/R2023b/projects/appearances/protos/HammeredCopper.proto"
EXTERNPROTO "https://raw.githubusercontent.com/cyberbotics/webots/R2023b/projects/appearances/protos/SandyGround.proto"
EXTERNPROTO "https://raw.githubusercontent.com/cyberbotics/webots/R2023b/projects/appearances/protos/SolarCell.proto"
EXTERNPROTO "https://raw.githubusercontent.com/cyberbotics/webots/R2023b/projects/objects/backgrounds/protos/TexturedBackground.proto"
EXTERNPROTO "https://raw.githubusercontent.com/cyberbotics/webots/R2023b/projects/objects/backgrounds/protos/TexturedBackgroundLight.proto"
EXTERNPROTO "https://raw.githubusercontent.com/cyberbotics/webots/R2023b/projects/objects/floors/protos/UnevenTerrain.proto"
EXTERNPROTO "https://raw.githubusercontent.com/cyberbotics/webots/R2023b/projects/appearances/protos/MetalStainlessSteelCable.proto"
EXTERNPROTO "https://raw.githubusercontent.com/cyberbotics/webots/R2023b/projects/appearances/protos/CorrugatedPvc.proto"
EXTERNPROTO "https://raw.githubusercontent.com/cyberbotics/webots/R2023b/projects/appearances/protos/ReflectiveSurface.proto"
EXTERNPROTO "https://raw.githubusercontent.com/cyberbotics/webots/R2023b/projects/appearances/protos/RoughPolymer.proto"

WorldInfo {
}
Viewpoint {
  orientation -0.015284787031133002 -0.9316918274206148 0.36292797357471357 5.823248625611207
  position -18.191121098103164 -1.219207912136594 3.7383051145556
}
TexturedBackground {
  texture "mars"
}
TexturedBackgroundLight {
  luminosity 2
}
UnevenTerrain {
  appearance SandyGround {
    colorOverride 0.55 0.55 0.4
    textureTransform TextureTransform {
      scale 50 50
    }
  }
}
Robot {
  translation -15.38226283926395 -2.557149013240386 2.733036784336574
  rotation 0.01180089085551438 -0.0642207785638101 -0.9978659381779069 0.8904754444766317
  children [
    Solid {
      translation -0.31 0.02 0.29
      children [
        SliderJoint {
          jointParameters JointParameters {
          }
          device [
            LinearMotor {
              name "cam_slider"
            }
          ]
          endPoint Solid {
            rotation 0 0 1 3.14158
            children [
              Camera {
                lens Lens {
                }
                focus Focus {
                }
                zoom Zoom {
                }
                recognition Recognition {
                }
                lensFlare LensFlare {
                }
              }
              Shape {
                appearance RoughPolymer {
                }
                geometry Box {
                  size 0.05 0.05 0.05
                }
              }
            ]
            name "endpoint_null"
          }
        }
        Shape {
          appearance Copper {
          }
          geometry Cylinder {
            height 0.6
            radius 0.02
          }
        }
      ]
      name "cam_stand"
    }
    DistanceSensor {
      translation -0.35 0.17 0
      rotation 0 0 1 3.14159
      children [
        DEF ds Shape {
          appearance ReflectiveSurface {
          }
          geometry Box {
            size 0.05 0.05 0.05
          }
        }
      ]
      name "ds2"
      boundingObject USE ds
      physics Physics {
        mass 1
      }
      lookupTable [
        0 0 0
        1 1000 0
      ]
    }
    DistanceSensor {
      translation -0.35 -0.19 0
      rotation 0 0 1 -3.1415853071795863
      children [
        DEF ds Shape {
          appearance ReflectiveSurface {
          }
          geometry Box {
            size 0.05 0.05 0.05
          }
        }
      ]
      name "ds1"
      boundingObject USE ds
      physics Physics {
        mass 1
      }
      lookupTable [
        0 0 0
        1 1000 0
      ]
    }
    DEF body Shape {
      appearance HammeredCopper {
      }
      geometry Box {
        size 0.7 0.5 0.2
      }
    }
    Solid {
      translation 0 0 0.19
      children [
        DEF panel Shape {
          appearance SolarCell {
          }
          geometry Box {
            size 0.8 0.5 0.01
          }
        }
        Solid {
          translation 0.3 -0.19 -0.05
          children [
            Shape {
              appearance Copper {
              }
              geometry Cylinder {
                height 0.1
                radius 0.02
              }
            }
          ]
          name "solar_panel_support1"
        }
        Solid {
          translation 0.3 0.19 -0.05
          children [
            Shape {
              appearance Copper {
              }
              geometry Cylinder {
                height 0.1
                radius 0.02
              }
            }
          ]
          name "solar_panel_support2"
        }
        Solid {
          translation -0.3 0.19 -0.05
          children [
            Shape {
              appearance Copper {
              }
              geometry Cylinder {
                height 0.1
                radius 0.02
              }
            }
          ]
          name "solar_panel_support3"
        }
        Solid {
          translation -0.3 -0.19 -0.05
          children [
            Shape {
              appearance Copper {
              }
              geometry Cylinder {
                height 0.1
                radius 0.02
              }
            }
          ]
          name "solar_panel_support4"
        }
      ]
      name "solar_panel"
    }
    Solid {
      translation -0.18 -0.24 0
      children [
        Solid {
          translation -0.120177 -0.0173275 -0.0500647
          rotation -0.9999999929357695 8.124469320562993e-05 -8.676267159571073e-05 1.5708626067521982
          children [
            DEF cylinder1 Shape {
              appearance CorrugatedPvc {
                colorOverride 0.333333 0 0
              }
              geometry Cylinder {
                height 0.09
                radius 0.02
              }
            }
            Solid {
              translation 0 0 -0.05
              children [
                DEF sphere1 Shape {
                  appearance BrushedSteel {
                  }
                  geometry Sphere {
                    radius 0.02
                  }
                }
                Solid {
                  translation 0 0.05 2.30588e-07
                  rotation -1 0 0 -1.5707953071795862
                  children [
                    DEF cylinder2 Shape {
                      appearance CorrugatedPvc {
                        colorOverride 0.333333 0 0
                      }
                      geometry Cylinder {
                        height 0.1
                        radius 0.02
                      }
                    }
                    Solid {
                      translation 0 0 -0.05
                      children [
                        DEF sphere1 Shape {
                          appearance BrushedSteel {
                          }
                          geometry Sphere {
                            radius 0.02
                          }
                        }
                        Solid {
                          translation 0 -0.03 -9.99999e-08
                          rotation 1 0 0 1.5708
                          children [
                            DEF cylinder3 Shape {
                              appearance CorrugatedPvc {
                                colorOverride 0.333333 0 0
                              }
                              geometry Cylinder {
                                height 0.06
                                radius 0.02
                              }
                            }
                            HingeJoint {
                              jointParameters HingeJointParameters {
                                position 405.74379422186365
                                axis 0 0 1
                                anchor -9.51224e-05 0.00113507 0.0800056
                              }
                              device [
                                RotationalMotor {
                                  name "wheel1_left"
                                }
                              ]
                              endPoint Solid {
                                translation -7.132613254077198e-06 0.000987429268618254 0.08008272559140828
                                rotation 5.726926782976216e-06 -6.67622377369446e-06 -0.9999999999613152 2.651372584402945
                                children [
                                  DEF wheel Shape {
                                    appearance MetalStainlessSteelCable {
                                    }
                                    geometry Cylinder {
                                      height 0.15
                                      radius 0.15
                                    }
                                  }
                                ]
                                boundingObject USE wheel
                                physics Physics {
                                  mass 1
                                }
                                linearVelocity -1.610583213167871e-05 -1.3804355095508038e-06 -5.056592087840367e-07
                                angularVelocity -2.103654679734167e-06 -1.3395922979774177e-06 2.5082674527741333e-06
                              }
                            }
                          ]
                          boundingObject USE cylinder3
                          physics DEF phy1 Physics {
                            mass 1
                          }
                        }
                      ]
                      name "solid(1)"
                      boundingObject USE sphere1
                      physics USE phy1
                    }
                  ]
                  boundingObject USE cylinder2
                  physics USE phy1
                }
              ]
              boundingObject USE sphere1
              physics USE phy1
            }
          ]
          boundingObject USE cylinder1
          physics USE phy1
        }
      ]
      name "wheel1_left_system"
      boundingObject USE body
      physics DEF phy1 Physics {
        mass 1
      }
    }
    Solid {
      translation 0.18 -0.24 0
      children [
        Solid {
          translation 0.119826 -0.0173636 -0.0599431
          rotation -0.9999999930027248 7.374603208071159e-05 -9.249904417794078e-05 1.5708786387286822
          children [
            DEF cylinder1 Shape {
              appearance CorrugatedPvc {
                colorOverride 0.333333 0 0
              }
              geometry Cylinder {
                height 0.09
                radius 0.02
              }
            }
            Solid {
              translation 0 0 -0.05
              children [
                DEF sphere1 Shape {
                  appearance BrushedSteel {
                  }
                  geometry Sphere {
                    radius 0.02
                  }
                }
                Solid {
                  translation 0 0.05 2.30588e-07
                  rotation -1 0 0 -1.5707953071795862
                  children [
                    DEF cylinder2 Shape {
                      appearance CorrugatedPvc {
                        colorOverride 0.333333 0 0
                      }
                      geometry Cylinder {
                        height 0.1
                        radius 0.02
                      }
                    }
                    Solid {
                      translation 0 0 -0.05
                      children [
                        DEF sphere1 Shape {
                          appearance BrushedSteel {
                          }
                          geometry Sphere {
                            radius 0.02
                          }
                        }
                        Solid {
                          translation 0 -0.03 -9.99999e-08
                          rotation 1 0 0 1.5708
                          children [
                            DEF cylinder3 Shape {
                              appearance CorrugatedPvc {
                              }
                              geometry Cylinder {
                                height 0.06
                                radius 0.02
                              }
                            }
                            HingeJoint {
                              jointParameters HingeJointParameters {
                                position 77.20598990782103
                                axis 0 0 1
                                anchor 0.000341778 0.000558794 0.0800055
                              }
                              device [
                                RotationalMotor {
                                  name "wheel2_left"
                                }
                              ]
                              endPoint Solid {
                                translation 0.0020429192116674304 -6.979990644247268e-05 0.07998886736145039
                                rotation 3.655322583616378e-06 2.8919236420877117e-06 -0.9999999999891377 4.464665091803891
                                children [
                                  DEF wheel Shape {
                                    appearance MetalStainlessSteelCable {
                                    }
                                    geometry Cylinder {
                                      height 0.15
                                      radius 0.15
                                    }
                                  }
                                ]
                                boundingObject USE wheel
                                physics Physics {
                                  mass 1
                                }
                                linearVelocity -1.4886948905335364e-05 -3.953411952155595e-07 -6.247239523418212e-07
                                angularVelocity -2.920043377715726e-06 -2.003167378807153e-06 2.4737031322780835e-06
                              }
                            }
                          ]
                          boundingObject USE cylinder3
                          physics DEF phy1 Physics {
                            mass 1
                          }
                        }
                      ]
                      name "solid(1)"
                      boundingObject USE sphere1
                      physics USE phy1
                    }
                  ]
                  boundingObject USE cylinder2
                  physics USE phy1
                }
              ]
              boundingObject USE sphere1
              physics USE phy1
            }
          ]
          boundingObject USE cylinder1
          physics USE phy1
        }
      ]
      name "wheel2_left_system"
      boundingObject USE body
      physics USE phy1
    }
    Solid {
      translation -0.18 0.24 0
      children [
        Solid {
          translation -0.130177 0.0173549 -0.050065
          rotation -0.9999999929357695 8.124469320562993e-05 -8.676267159571073e-05 1.5708626067521982
          children [
            DEF cylinder1 Shape {
              appearance CorrugatedPvc {
                colorOverride 0.333333 0 0
              }
              geometry Cylinder {
                height 0.09
                radius 0.02
              }
            }
            Solid {
              translation 0 0 0.05
              children [
                DEF sphere1 Shape {
                  appearance BrushedSteel {
                  }
                  geometry Sphere {
                    radius 0.02
                  }
                }
                Solid {
                  translation 0 0.05 2.30588e-07
                  rotation -1 0 0 -1.5707953071795862
                  children [
                    DEF cylinder2 Shape {
                      appearance CorrugatedPvc {
                        colorOverride 0.333333 0 0
                      }
                      geometry Cylinder {
                        height 0.1
                        radius 0.02
                      }
                    }
                    Solid {
                      translation 0 0 -0.05
                      children [
                        DEF sphere1 Shape {
                          appearance BrushedSteel {
                          }
                          geometry Sphere {
                            radius 0.02
                          }
                        }
                        Solid {
                          translation 0 0.03 -9.99999e-08
                          rotation 1 0 0 1.5708
                          children [
                            DEF cylinder3 Shape {
                              appearance CorrugatedPvc {
                                colorOverride 0.333333 0 0
                              }
                              geometry Cylinder {
                                height 0.06
                                radius 0.02
                              }
                            }
                            HingeJoint {
                              jointParameters HingeJointParameters {
                                position 432.5787204233856
                                axis 0 0 1
                                anchor 0.00237208 0.000614304 -0.0799754
                              }
                              device [
                                RotationalMotor {
                                  name "wheel1_right"
                                }
                              ]
                              endPoint Solid {
                                translation 0.0013630973480609323 0.0007768389624479338 -0.07992914989600486
                                rotation -0.2833784208336414 0.9590081702399575 -4.340547394949736e-06 3.1416015225907983
                                children [
                                  DEF wheel Shape {
                                    appearance MetalStainlessSteelCable {
                                    }
                                    geometry Cylinder {
                                      height 0.15
                                      radius 0.15
                                    }
                                  }
                                ]
                                boundingObject USE wheel
                                physics Physics {
                                  mass 1
                                }
                                linearVelocity -1.7481262780840715e-05 2.8817716718913793e-07 -7.484604559522803e-07
                                angularVelocity -1.937169997842018e-06 -1.2042370246946247e-06 2.515326943650326e-06
                              }
                            }
                          ]
                          boundingObject USE cylinder3
                          physics DEF phy1 Physics {
                            mass 1
                          }
                        }
                      ]
                      name "solid(1)"
                      boundingObject USE sphere1
                      physics USE phy1
                    }
                  ]
                  boundingObject USE cylinder2
                  physics USE phy1
                }
              ]
              boundingObject USE sphere1
              physics USE phy1
            }
          ]
          boundingObject USE cylinder1
          physics USE phy1
        }
      ]
      name "wheel1_right_system"
      boundingObject USE body
      physics DEF phy1 Physics {
        mass 1
      }
    }
    Solid {
      translation 0.18 0.24 0
      children [
        Solid {
          translation 0.139823 0.0173083 -0.0600629
          rotation -0.9999999929357695 8.124469320562993e-05 -8.676267159571073e-05 1.5708626067521982
          children [
            DEF cylinder1 Shape {
              appearance CorrugatedPvc {
                colorOverride 0.333333 0 0
              }
              geometry Cylinder {
                height 0.09
                radius 0.02
              }
            }
            Solid {
              translation 0 0 0.05
              children [
                DEF sphere1 Shape {
                  appearance BrushedSteel {
                  }
                  geometry Sphere {
                    radius 0.02
                  }
                }
                Solid {
                  translation 0 0.05 2.30588e-07
                  rotation -1 0 0 -1.5707953071795862
                  children [
                    DEF cylinder2 Shape {
                      appearance CorrugatedPvc {
                        colorOverride 0.333333 0 0
                      }
                      geometry Cylinder {
                        height 0.1
                        radius 0.02
                      }
                    }
                    Solid {
                      translation 0 0 -0.05
                      children [
                        DEF sphere1 Shape {
                          appearance BrushedSteel {
                          }
                          geometry Sphere {
                            radius 0.02
                          }
                        }
                        Solid {
                          translation 0 0.03 -9.99999e-08
                          rotation 1 0 0 1.5708
                          children [
                            DEF cylinder3 Shape {
                              appearance CorrugatedPvc {
                                colorOverride 0.333333 0 0
                              }
                              geometry Cylinder {
                                height 0.06
                                radius 0.02
                              }
                            }
                            HingeJoint {
                              jointParameters HingeJointParameters {
                                position 425.749290248577
                                axis 0 0 1
                                anchor 0.00237208 0.000614304 -0.0799754
                              }
                              device [
                                RotationalMotor {
                                  name "wheel2_right"
                                }
                              ]
                              endPoint Solid {
                                translation 0.001571313207560621 0.0030407643321125532 -0.07986699019610466
                                rotation -0.014191290314070114 0.9998992985691464 -3.8862896698009564e-07 3.141567101791231
                                children [
                                  DEF wheel Shape {
                                    appearance MetalStainlessSteelCable {
                                    }
                                    geometry Cylinder {
                                      height 0.15
                                      radius 0.15
                                    }
                                  }
                                ]
                                boundingObject USE wheel
                                physics Physics {
                                  mass 1
                                }
                                linearVelocity -1.6208728878453373e-05 1.3236860705143635e-06 -8.754718804766572e-07
                                angularVelocity -2.1988471924241938e-06 -1.4166105415591552e-06 2.5042290064401336e-06
                              }
                            }
                          ]
                          boundingObject USE cylinder3
                          physics DEF phy1 Physics {
                            mass 1
                          }
                        }
                      ]
                      name "solid(1)"
                      boundingObject USE sphere1
                      physics USE phy1
                    }
                  ]
                  boundingObject USE cylinder2
                  physics USE phy1
                }
              ]
              boundingObject USE sphere1
              physics USE phy1
            }
          ]
          boundingObject USE cylinder1
          physics USE phy1
        }
      ]
      name "wheel2_right_system"
      boundingObject USE body
      physics DEF phy1 Physics {
        mass 1
      }
    }
  ]
  boundingObject USE body
  physics DEF phy Physics {
    mass 1
  }
  controller "mars_rover"
  linearVelocity -1.620141559038178e-05 -9.760231189185712e-08 -6.817032498036968e-07
  angularVelocity -2.2423596264459627e-08 3.523525592727648e-07 2.5965318365509495e-06
}
Pose {
  translation -10.07 -2.35 3.34
  children [
    Shape {
      appearance PBRAppearance {
        metalness 0
      }
      geometry Cylinder {
        height 1
      }
    }
  ]
}
